Workbook

Sheet Résumé
A1: Leads Asie du Sud-Est — Magasins de vinyles & revendeurs de cartes Pokémon
A2: Recherche web réalisée le 08/10/2026 — Thaïlande, Vietnam, Philippines, Singapour, Indonésie
A4: Pays | B4: Vinyles | C4: Vinyles statut « Actif » | D4: Vinyles avec ≥1 contact | E4: Pokémon | F4: Pokémon priorité A | G4: Pokémon priorité B | H4: Pokémon avec ≥1 contact
A5: Thaïlande | B5: =COUNTIF(Vinyles!$C:$C,$A5) -> 39 | C5: =COUNTIFS(Vinyles!$C:$C,$A5,Vinyles!$Q:$Q,"Actif") -> 19 | D5: =COUNTIFS(Vinyles!$C:$C,$A5,Vinyles!$R:$R,">0") -> 13 | E5: =COUNTIF(Pokémon!$C:$C,$A5) -> 45 | F5: =COUNTIFS(Pokémon!$C:$C,$A5,Pokémon!$I:$I,"A") -> 7 | G5: =COUNTIFS(Pokémon!$C:$C,$A5,Pokémon!$I:$I,"B") -> 6 | H5: =COUNTIFS(Pokémon!$C:$C,$A5,Pokémon!$U:$U,">0") -> 35
A6: Vietnam | B6: =COUNTIF(Vinyles!$C:$C,$A6) -> 32 | C6: =COUNTIFS(Vinyles!$C:$C,$A6,Vinyles!$Q:$Q,"Actif") -> 5 | D6: =COUNTIFS(Vinyles!$C:$C,$A6,Vinyles!$R:$R,">0") -> 26 | E6: =COUNTIF(Pokémon!$C:$C,$A6) -> 33 | F6: =COUNTIFS(Pokémon!$C:$C,$A6,Pokémon!$I:$I,"A") -> 4 | G6: =COUNTIFS(Pokémon!$C:$C,$A6,Pokémon!$I:$I,"B") -> 7 | H6: =COUNTIFS(Pokémon!$C:$C,$A6,Pokémon!$U:$U,">0") -> 20
A7: Philippines | B7: =COUNTIF(Vinyles!$C:$C,$A7) -> 53 | C7: =COUNTIFS(Vinyles!$C:$C,$A7,Vinyles!$Q:$Q,"Actif") -> 5 | D7: =COUNTIFS(Vinyles!$C:$C,$A7,Vinyles!$R:$R,">0") -> 28 | E7: =COUNTIF(Pokémon!$C:$C,$A7) -> 54 | F7: =COUNTIFS(Pokémon!$C:$C,$A7,Pokémon!$I:$I,"A") -> 8 | G7: =COUNTIFS(Pokémon!$C:$C,$A7,Pokémon!$I:$I,"B") -> 11 | H7: =COUNTIFS(Pokémon!$C:$C,$A7,Pokémon!$U:$U,">0") -> 25
A8: Singapour | B8: =COUNTIF(Vinyles!$C:$C,$A8) -> 35 | C8: =COUNTIFS(Vinyles!$C:$C,$A8,Vinyles!$Q:$Q,"Actif") -> 15 | D8: =COUNTIFS(Vinyles!$C:$C,$A8,Vinyles!$R:$R,">0") -> 17 | E8: =COUNTIF(Pokémon!$C:$C,$A8) -> 78 | F8: =COUNTIFS(Pokémon!$C:$C,$A8,Pokémon!$I:$I,"A") -> 7 | G8: =COUNTIFS(Pokémon!$C:$C,$A8,Pokémon!$I:$I,"B") -> 36 | H8: =COUNTIFS(Pokémon!$C:$C,$A8,Pokémon!$U:$U,">0") -> 52
A9: Indonésie | B9: =COUNTIF(Vinyles!$C:$C,$A9) -> 56 | C9: =COUNTIFS(Vinyles!$C:$C,$A9,Vinyles!$Q:$Q,"Actif") -> 11 | D9: =COUNTIFS(Vinyles!$C:$C,$A9,Vinyles!$R:$R,">0") -> 30 | E9: =COUNTIF(Pokémon!$C:$C,$A9) -> 61 | F9: =COUNTIFS(Pokémon!$C:$C,$A9,Pokémon!$I:$I,"A") -> 5 | G9: =COUNTIFS(Pokémon!$C:$C,$A9,Pokémon!$I:$I,"B") -> 22 | H9: =COUNTIFS(Pokémon!$C:$C,$A9,Pokémon!$U:$U,">0") -> 32
A10: Total | B10: =SUM(B5:B9) -> 215 | C10: =SUM(C5:C9) -> 55 | D10: =SUM(D5:D9) -> 114 | E10: =SUM(E5:E9) -> 271 | F10: =SUM(F5:F9) -> 31 | G10: =SUM(G5:G9) -> 82 | H10: =SUM(H5:H9) -> 164
A12: Comment lire le fichier
A13: • Onglet « Vinyles » : disquaires physiques, stands de marché, cafés/bars et boutiques hi-fi qui vendent des vinyles, vendeurs en ligne (site, Shopee/Lazada/Tokopedia, Instagram/Facebook, Discogs), labels/distributeurs.
A14: • Onglet « Pokémon » : boutiques TCG et revendeurs de cartes Pokémon, triés par pays puis par taille. « Gros items (preuves) » = ce qui a été vu dans les sources (booster boxes, cases, ETB, slabs PSA/BGS/CGC, vintage…).
A15: • Taille reseller : Gros = gros revendeur / distributeur / chaîne / grosse boutique en ligne ; Moyen = boutique dédiée vendant des boîtes scellées ; Petit = petit vendeur ; Inconnu = pas assez d'info.
A16: • Priorité (formule) : A = taille « Gros », ou gros items prouvés + vente en live ; B = taille « Moyen » ou gros items prouvés ; C = le reste.
A17: • Statut : Actif = activité vue en 2024-2026 ; Non vérifié = pas de preuve récente ; Peut-être fermé = une source évoque une fermeture (à vérifier avant contact).
A18: • Nb canaux de contact (formule) = nombre de champs remplis parmi Site web, Instagram, Facebook, TikTok, Téléphone, Email.
A19: • Google Maps : « Voir sur Maps » = lien trouvé dans les sources ; « Rechercher sur Maps » = lien de recherche généré à partir du nom et de l'adresse (boutiques physiques uniquement).
A20: Méthode et limites
A21: • Données collectées par recherche web (guides, annuaires, articles, forums, profils Instagram/Facebook/TikTok, boutiques Shopee/Lazada/Tokopedia/Carousell/Discogs), en anglais et en langues locales.
A22: • Chaque ligne cite au moins une source (colonne « Sources », la première est cliquable). Aucun contact n'a été inventé : un champ vide signifie que l'information n'a pas été trouvée.
A23: • Les petites boutiques changent vite (déménagements, fermetures, changement de compte Instagram) : vérifier le compte avant toute prise de contact.
A24: • Doublons fusionnés automatiquement (même nom, même Instagram, même page Facebook ou même site web dans un pays).

Sheet Vinyles
A1: # | B1: Nom | C1: Pays | D1: Ville | E1: Adresse / zone | F1: Type | G1: Spécialité | H1: Site web | I1: Instagram | J1: Facebook | K1: TikTok | L1: Téléphone / WhatsApp | M1: Email | N1: Marketplaces (Shopee, Lazada, Discogs…) | O1: Google Maps | P1: Vente en live | Q1: Statut | R1: Nb canaux de contact | S1: Notes | T1: Sources
A2: 1 | B2: 1979 Vinyl | C2: Thaïlande | D2: Bangkok | E2: 3rd floor, Fortune Town, 1 Ratchadaphisek Rd (MRT Rama 9) - per Asia City | F2: Boutique physique | G2: Secondhand oldies, rock, obscure 90s; Thorens turntables | J2: https://www.facebook.com/1979vinyl | O2: Rechercher sur Maps | Q2: Non vérifié | R2: =COUNTA(H2:M2) -> 1 | S2: Asia City listing; BK also gives Black Amber/Bungkumhouse address for 1979 Vinyls - may be related. | T2: https://bk.asia-city.com/shopping/article/best-shops-buy-vinyl-records-portable-turntables-bangkok-3
A3: 2 | B3: 242 Record Store | C3: Thaïlande | D3: Bangkok | E3: Room 242, 2nd floor, River City Bangkok, Charoen Krung 24, Bangkok | F3: Boutique physique | G3: Vinyl, CDs, tapes, posters, merch | I3: https://www.instagram.com/242recordsstore | O3: Rechercher sur Maps | Q3: Non vérifié | R3: =COUNTA(H3:M3) -> 1 | S3: ~3,200 IG followers; related label account @242records_bkk. | T3: https://www.instagram.com/242recordsstore/
A4: 3 | B4: Baa Records | C4: Thaïlande | D4: Bangkok | E4: Small storefront on Charoen Krung Rd (Entertainment Project), Bangkok; main base in Songkhla | F4: Boutique physique | G4: Vinyl records | O4: Rechercher sur Maps | Q4: Non vérifié | R4: =COUNTA(H4:M4) -> 0 | S4: Main base in Songkhla province with a Bangkok storefront per Time Out (Thai). | T4: https://www.timeout.com/bangkok/th/music/entertainment-project
A5: 4 | B5: Bungkumhouse Records | C5: Thaïlande | D5: Bangkok | E5: 4th floor, Black Amber Building, Sukhumvit Soi 55 (Thonglor, between Soi 5 and 7), Bangkok | F5: Boutique physique | G5: 80s-90s classics, Britpop, alt rock, soul, funk, electronica; local Thai indie releases | L5: 086-606-2230 | O5: Rechercher sur Maps | Q5: Actif | R5: =COUNTA(H5:M5) -> 1 | S5: Also spelled Burngkumhouse. Open Wed/Tue-Sun 1pm-9pm. BK Magazine lists 1979 Vinyls at the same Black Amber address/phone. | T5: https://www.timeout.com/bangkok/shopping/burngkumhouse-records | https://www.bkmagazine.com/arts-culture/where-to-find-bangkoks-best-record-stores-and-vinyl-bars/ | https://www.bkmagazine.com/nightlife/bangkok-bar-club/1979-cafe-and-unknown-pleasures/
A6: 5 | B6: CD Cosmos | C6: Thaïlande | D6: Bangkok | E6: Chatuchak, Bangkok | F6: Boutique physique | G6: Records and CDs | O6: Rechercher sur Maps | Q6: Non vérifié | R6: =COUNTA(H6:M6) -> 0 | S6: Listed in Time Out Bangkok (Thai) record shop guide. | T6: https://www.timeout.com/bangkok/th/music/cd-cosmos
A7: 6 | B7: Coconut Records | C7: Thaïlande | D7: Bangkok | E7: Room 3027, 3rd floor, Fortune Town, Ratchadaphisek Rd, Din Daeng, Bangkok | F7: Boutique physique | G7: Thai 90s releases, classic luk thung and molam; used vinyl | O7: Rechercher sur Maps | Q7: Non vérifié | R7: =COUNTA(H7:M7) -> 0 | S7: Open 11:30am-8pm daily; check Facebook for event closures. | T7: https://www.timeout.com/bangkok/music/coconut-records
A8: 7 | B8: DP Music | C8: Thaïlande | D8: Bangkok | E8: Building near MRT Rama 9, Bangkok | F8: Boutique physique | G8: Vinyl records | O8: Rechercher sur Maps | Q8: Non vérifié | R8: =COUNTA(H8:M8) -> 0 | S8: Listed in Time Out Bangkok (Thai) record shop guide. | T8: https://www.timeout.com/bangkok/th/music/dp-music
A9: 8 | B9: Fat Black Record | C9: Thaïlande | D9: Bangkok | E9: 345 Thara Rom Alley, Hua Mak, Bang Kapi, Bangkok | F9: Boutique physique | G9: New pressings plus some vintage; hi-fi gear and turntables (Crosley to Rega) | L9: 087-124-4421 | O9: Rechercher sur Maps | Q9: Actif | R9: =COUNTA(H9:M9) -> 1 | S9: Time Out Bangkok guide. Open daily noon-8pm. | T9: https://www.timeout.com/bangkok/shopping/fat-black-record | https://www.timeout.com/bangkok/music/best-record-shops-in-bangkok
A10: 9 | B10: Format BKK | C10: Thaïlande | D10: Bangkok | E10: Charoen Phon 1 Alley, Ari, Phaya Thai, Bangkok | F10: Boutique physique | G10: Offbeat Thai and international releases, 60s-90s secondhand; turntables (Gadhouse brand); sleeve-painting workshops | O10: Rechercher sur Maps | Q10: Actif | R10: =COUNTA(H10:M10) -> 0 | S10: Linked to Gadhouse turntable brand. Open daily 11am-8pm. New addition to Time Out 2026 guide. | T10: https://www.timeout.com/bangkok/music/best-record-shops-in-bangkok | https://www.timeout.com/bangkok/things-to-do/paint-vinyl-records-at-format-bkk
A11: 10 | B11: Garage Records | C11: Thaïlande | D11: Bangkok | E11: Lad Phrao Soi 8 (Yaek 9), Bangkok | F11: Boutique physique | G11: Rare finds, 80s-90s alternative rock | O11: Rechercher sur Maps | Q11: Non vérifié | R11: =COUNTA(H11:M11) -> 0 | S11: Listed by BK Magazine. Listed in BK Magazine roundup (date uncertain, 2019-2025). | T11: https://www.bkmagazine.com/arts-culture/where-to-find-bangkoks-best-record-stores-and-vinyl-bars/
A12: 11 | B12: Get Back and Jude Records | C12: Thaïlande | D12: Bangkok | E12: 399 Thanon Yaowaphanit, Samphanthawong (Yaowarat/Song Wat), Bangkok; pop-ups at Siam Discovery 2F and Siam Paragon 5F (Nextopia) | F12: Boutique physique | G12: Vinyl, esp. 7-inch singles and early pressings | O12: Rechercher sur Maps | Q12: Actif | R12: =COUNTA(H12:M12) -> 0 | S12: Time Out Bangkok 2026 guide. Open 11am-8pm daily. Has mall pop-up outposts. | T12: https://www.timeout.com/bangkok/music/get-back-and-jude-records | https://www.timeout.com/bangkok/music/best-record-shops-in-bangkok
A13: 12 | B13: Hall of Fame Records | C13: Thaïlande | D13: Bangkok | E13: 3rd floor (3058), Fortune Town, Ratchadaphisek Rd, Din Daeng, Bangkok | F13: Boutique physique | G13: Used & new vinyl; international and Thai hits; classic rock, country, European ambient; claims 40,000+ titles | O13: Rechercher sur Maps | Q13: Actif | R13: =COUNTA(H13:M13) -> 0 | S13: Once had several branches (incl. Thanya Shopping Park, Srinakarin); now one walk-in store at Fortune Town. Open 1pm-8pm daily. Possibly Bangkok's biggest record shop. | T13: https://www.timeout.com/bangkok/shopping/hall-of-fame-records | https://www.timeout.com/bangkok/music/best-record-shops-in-bangkok | https://citynomads.com/8-records-stores-in-bangkok-for-vinyl-music-cassettes-and-cds/
A14: 13 | B14: HAVE YOU HEARD? Records | C14: Thaïlande | D14: Bangkok | E14: Entertainment Project, 1107 Si Phraya Rd (Charoen Krung 43 area), Bang Rak, Bangkok | F14: Boutique physique | G14: Indie/alternative, soul, funk, hip-hop, house, techno; new vinyl | O14: Rechercher sur Maps | Q14: Actif | R14: =COUNTA(H14:M14) -> 0 | S14: Founded 2021 by indie promoters. Open Wed/Thu/Sun 12-8pm, Fri-Sat until midnight; closed Mon-Tue. | T14: https://www.timeout.com/bangkok/music/have-you-heard-records-entertainment-project | https://www.timeout.com/bangkok/music/best-record-shops-in-bangkok
A15: 14 | B15: More Rice Records | C15: Thaïlande | D15: Bangkok | E15: Sukhumvit Soi 31 / Phrom Phong back sois (near BTS Phrom Phong), Bangkok | F15: Boutique + en ligne | G15: House, techno, electronic; new second-hand stock every Thursday; label 'Made in Asia since 2016' | I15: https://www.instagram.com/morericerecords | O15: Rechercher sur Maps | Q15: Non vérifié | R15: =COUNTA(H15:M15) -> 1 | S15: Club-music label turned record store, store opened March 2021. Store IG @morerice.recordstore; hours Tue-Fri 1-8pm, Sat 3-8pm; new secondhand stock every Thursday. | T15: https://www.instagram.com/morericerecords/ | https://www.instagram.com/morerice.recordstore/ | https://www.bkmagazine.com/arts-culture/where-to-find-bangkoks-best-record-stores-and-vinyl-bars/ | https://thestandard.co/pop-cast-more-rice-record-store-playlist/
A16: 15 | B16: Nong Taprachan | C16: Thaïlande | D16: Bangkok | E16: 14 Tha Prachan (Wang Lang / Rot Fai Pier Alley area), Phra Borom Maha Ratchawang, Phra Nakhon, Bangkok | F16: Boutique physique | G16: New and classic Thai albums, Thai music past and present, some metal | O16: Rechercher sur Maps | Q16: Actif | R16: =COUNTA(H16:M16) -> 0 | S16: #1 in Time Out Bangkok record shop guide (Feb 2026). Open daily 11am-6:30pm; hosts young band sets. | T16: https://www.timeout.com/bangkok/music/nong-taprachan | https://www.timeout.com/bangkok/music/best-record-shops-in-bangkok
A17: 16 | B17: PPrecordsrecords | C17: Thaïlande | D17: Bangkok | F17: Vendeur réseaux sociaux | G17: Vinyl records; worldwide shipping; orders via DM | I17: https://www.instagram.com/pprecordsrecords | Q17: Non vérifié | R17: =COUNTA(H17:M17) -> 1 | S17: Online seller based in Bangkok. | T17: https://www.instagram.com/pprecordsrecords/
A18: 17 | B18: Record Record. | C18: Thaïlande | D18: Bangkok | E18: Pop-up at Foundry Creative Hub (per IG) | F18: Boutique + en ligne | G18: Vinyl records and turntables | I18: https://www.instagram.com/recordrecord.th | O18: Rechercher sur Maps | Q18: Non vérifié | R18: =COUNTA(H18:M18) -> 1 | S18: ~22K IG followers; pop-up open 12-8pm, closed Mondays. | T18: https://www.instagram.com/recordrecord.th/
A19: 18 | B19: Record Shop (Raan Pan Sieng) | C19: Thaïlande | D19: Bangkok | E19: 3 Soi Pradiphat 19, Pradiphat Rd, Samsen Nai, Phaya Thai, Bangkok | F19: Boutique physique | G19: Vintage and current albums, rare items; Thai cassettes and LPs | O19: Rechercher sur Maps | Q19: Actif | R19: =COUNTA(H19:M19) -> 0 | S19: Listed in Time Out Bangkok record shop guide. Open 10:30am-9pm. | T19: https://www.timeout.com/bangkok/shopping/record-shop-raan-pan-sieng | https://www.timeout.com/bangkok/music/best-record-shops-in-bangkok
A20: 19 | B20: Record This | C20: Thaïlande | D20: Bangkok | E20: 3rd floor, Central Ladprao, Bangkok | F20: Boutique + en ligne | G20: Vinyl records | I20: https://www.instagram.com/recordthis_vinyl | O20: Rechercher sur Maps | Q20: Non vérifié | R20: =COUNTA(H20:M20) -> 1 | S20: Bangkok-based; ~1,300 IG followers. | T20: https://www.instagram.com/recordthis_vinyl/
A21: 20 | B21: recordoffee (record & coffee) | C21: Thaïlande | D21: Bangkok | E21: Charoen Krung 29, Bangkok | F21: Café / bar avec boutique | G21: Records + coffee | I21: https://www.instagram.com/recordoffee | O21: Rechercher sur Maps | Q21: Non vérifié | R21: =COUNTA(H21:M21) -> 1 | S21: Weekdays 9:30-18:00, weekends 8:00-20:00, closed Tue. | T21: https://www.instagram.com/recordoffee/
A22: 21 | B22: Recoroom Vinyl & Vintage Audio | C22: Thaïlande | D22: Bangkok | E22: Building fronting Ekamai bus terminal (Ekkamai), Khlong Toei, Bangkok 10110 (older listings: Ekkamai 10 / Sukhumvit Soi 31 / Thetsaban Songkhro Rd, Chatuchak) | F22: Boutique physique | G22: Used/hand-picked vinyl: soul, funk, blues, rock; vintage audio equipment; listening turntable | O22: Rechercher sur Maps | Q22: Actif | R22: =COUNTA(H22:M22) -> 0 | S22: Time Out Bangkok 2026 guide; ranked #147 in The Vinyl Factory world's best record shops. Open daily ~11am-7pm. Address has moved several times - confirm. | T22: https://www.timeout.com/bangkok/music/recoroom-vinyl-and-vintage-audio | https://www.timeout.com/bangkok/music/best-record-shops-in-bangkok | https://thevinylfactory.com/features/the-worlds-best-record-shops-147-recoroom-vinyl-vintage-audio-bangkok
A23: 22 | B23: Sex Record Shop | C23: Thaïlande | D23: Bangkok | E23: 2nd floor, Seenspace, Thonglor Soi 13, Bangkok | F23: Boutique physique | G23: New & used LPs; 70s-80s heavy rock, 90s alternative, film soundtracks | L23: 02-185-2728 | O23: Rechercher sur Maps | Q23: Non vérifié | R23: =COUNTA(H23:M23) -> 1 | S23: Listed in BK Magazine 2019 roundup; no recent evidence seen. Listed in BK Magazine roundup (date uncertain, 2019-2025). | T23: https://www.bkmagazine.com/arts-culture/where-to-find-bangkoks-best-record-stores-and-vinyl-bars/ | https://bk.asia-city.com/shopping/article/best-shops-buy-vinyl-records-portable-turntables-bangkok
A24: 23 | B24: Tang Siang Thai | C24: Thaïlande | D24: Bangkok | E24: Charoenkrung Soi 11 (near MRT Sam Yot), Bangkok | F24: Boutique physique | G24: 60s-70s LPs, Thai and Chinese pressings; used | O24: Rechercher sur Maps | Q24: Non vérifié | R24: =COUNTA(H24:M24) -> 0 | S24: Old-school shop listed by BK Magazine. Listed in BK Magazine roundup (date uncertain, 2019-2025). | T24: https://www.bkmagazine.com/arts-culture/where-to-find-bangkoks-best-record-stores-and-vinyl-bars/
A25: 24 | B25: Tonchabab Record Shop | C25: Thaïlande | D25: Bangkok | E25: 10 Boonsiri Rd (Phra Nakhon) and Pattanakarn Rd branch, Bangkok | F25: Boutique physique | G25: Rare world music, luk thung, 60s-70s pop; used | O25: Rechercher sur Maps | Q25: Non vérifié | R25: =COUNTA(H25:M25) -> 0 | S25: Family-run, two branches, visits by appointment. Listed in BK Magazine roundup (date uncertain, 2019-2025). | T25: https://www.bkmagazine.com/arts-culture/where-to-find-bangkoks-best-record-stores-and-vinyl-bars/ | https://bk.asia-city.com/shopping/article/best-shops-buy-vinyl-records-portable-turntables-bangkok
A26: 25 | B26: Trackaddict Record | C26: Thaïlande | D26: Bangkok | E26: 47 MT&T Building, Soi Pridi Banomyong 3 (Sukhumvit 69 area), Watthana, Bangkok 10110 | F26: Boutique physique | G26: Used/rare vinyl from ~300 THB; rock, R&B, soul, soundtracks | O26: Rechercher sur Maps | Q26: Actif | R26: =COUNTA(H26:M26) -> 0 | S26: Also written Track Addict. Weekdays 9am-8pm, weekends noon-8pm. | T26: https://timeout.com/bangkok/shopping/trackaddict-record | https://citynomads.com/8-records-stores-in-bangkok-for-vinyl-music-cassettes-and-cds/
A27: 26 | B27: Vinyl & Toys | C27: Thaïlande | D27: Bangkok | E27: 19 Pradit Manutham Rd (near Bangkok Resort), Lat Phrao, Bangkok 10230 (Ramintra); second branch at Fortune Town, Ratchadaphisek Rd | F27: Boutique physique | G27: Large used stock leaning Japanese jazz and soul; toys; coffee | O27: Rechercher sur Maps | Q27: Actif | R27: =COUNTA(H27:M27) -> 0 | S27: Simon Grigg describes Fortune Town branch as two adjacent shops (full price + bargain). Ramintra main shop. | T27: https://www.timeout.com/bangkok/music/vinyl-toys | https://www.thebangkoknavigator.simongrigg.info/
A28: 27 | B28: Vinyl Die Hards | C28: Thaïlande | D28: Bangkok | E28: 162 Srinagarindra Rd (opposite Paradise Park, Srinakarin Soi 44), Prawet, Bangkok | F28: Boutique physique | G28: Used vinyl from ~100 THB; classics (jazz, rock, pop) | O28: Rechercher sur Maps | Q28: Non vérifié | R28: =COUNTA(H28:M28) -> 0 | S28: Run by child of PS Audio's owner (PS Audio closed). | T28: https://www.timeout.com/bangkok/shopping/vinyl-die-hards | https://citynomads.com/8-records-stores-in-bangkok-for-vinyl-music-cassettes-and-cds/
A29: 28 | B29: Vinyl Feeling | C29: Thaïlande | D29: Bangkok | E29: Warehouse 30, Charoenkrung Soi 30, Bang Rak, Bangkok; corner in Another Story, EmQuartier 4F | F29: Boutique physique | G29: Hip-hop, R&B, drum and bass vinyl | O29: Rechercher sur Maps | Q29: Non vérifié | R29: =COUNTA(H29:M29) -> 0 | S29: Listed in Asia City / BK roundups (c.2019-2021). | T29: https://bk.asia-city.com/shopping/article/best-shops-buy-vinyl-records-portable-turntables-bangkok | https://www.bkmagazine.com/city-living/shopping-article-best-shops-buy-vinyl-records-portable-turntables-bangkok/
A30: 29 | B30: Vinyllica Record Fortune Town | C30: Thaïlande | D30: Bangkok | E30: Fortune Town, Ratchadaphisek Rd, Bangkok | F30: Boutique physique | G30: Hard rock & heavy metal focus; Thai and international records | I30: https://www.instagram.com/vinyllica_record_fortunetown | O30: Rechercher sur Maps | Q30: Non vérifié | R30: =COUNTA(H30:M30) -> 1 | S30: Thai name ไวนิลลิกา ฟอร์จูนทาวน์. | T30: https://www.instagram.com/vinyllica_record_fortunetown/ | https://www.bkmagazine.com/arts-culture/where-to-find-bangkoks-best-record-stores-and-vinyl-bars/
A31: 30 | B31: Zubaidah Records | C31: Thaïlande | D31: Bangkok | E31: Between BTS Ekkamai and BTS Phra Khanong, Bangkok | F31: Boutique physique | G31: Vinyl records | O31: Rechercher sur Maps | Q31: Non vérifié | R31: =COUNTA(H31:M31) -> 0 | S31: Listed in Simon Grigg's Bangkok Navigator record shop guide (compiled c.2021). | T31: https://www.thebangkoknavigator.simongrigg.info/
A32: 31 | B32: Zudrangma Records | C32: Thaïlande | D32: Bangkok | E32: 7/1 Sukhumvit Soi 51, Khlong Tan Nuea, Watthana, Bangkok | F32: Boutique + en ligne | G32: Molam, luk thung, Thai funk, world music, disco; own label reissues; new & used | L32: +66 83 063 1335 | O32: Rechercher sur Maps | Q32: Actif | R32: =COUNTA(H32:M32) -> 1 | S32: Owned by DJ Maft Sai. Wed-Sun 12-8pm. Has web shop. 4.6 on Wanderlog (120+ reviews). | T32: https://wanderlog.com/place/details/1841365/zudrangma-records | https://www.timeout.com/bangkok/shopping/zudrangma-records | https://citynomads.com/8-records-stores-in-bangkok-for-vinyl-music-cassettes-and-cds/
A33: 32 | B33: Anglo Siam Record Shop | C33: Thaïlande | D33: Chiang Mai | E33: Loi Kroh Rd, Chiang Mai | F33: Boutique physique | G33: Imported rare grooves and scarce Thai pressings; drinks while browsing | O33: Rechercher sur Maps | Q33: Actif | R33: =COUNTA(H33:M33) -> 0 | S33: New shop opened by DJ outfit Anglo Siam (Time Out Chiang Mai opening listing, Jan 10 - after the c.2025 top-11 list). Opens from midday. | T33: https://www.timeout.com/chiang-mai/things-to-do/dig-into-rare-grooves-at-the-anglo-siam-record-shop-opening
A34: 33 | B34: Deaf Shop | C34: Thaïlande | D34: Chiang Mai | E34: Old town, Chiang Mai (near Nuii Bar, Pra Pok Klao Rd Soi 1) | F34: Café / bar avec boutique | G34: Vinyl listening bar and record store; large LP collection | O34: Rechercher sur Maps | Q34: Actif | R34: =COUNTA(H34:M34) -> 0 | S34: Opened May 2022 by Mum Pimolpud and Laurens Brouwer. Open Thu-Sat evenings and Sunday afternoons. | T34: https://mixmag.asia/read/chiang-mai-first-vinyl-listening-bar-deaf-shop-local | https://cnxmag.beehiiv.com/p/deaf-shop-is-a-vinyl-listening-gem | https://www.timeout.com/chiang-mai/music/chiang-mais-top-11-places-to-dig-for-vinyl
A35: 34 | B35: Franc Haus | C35: Thaïlande | D35: Chiang Mai | E35: Upstairs at Potto diner, Nimman, Chiang Mai | F35: Boutique physique | G35: New releases (largest new-release range in the city) | O35: Rechercher sur Maps | Q35: Actif | R35: =COUNTA(H35:M35) -> 0 | S35: Small record shop listed in Time Out Chiang Mai top 11 (c.2025). | T35: https://www.timeout.com/chiang-mai/music/chiang-mais-top-11-places-to-dig-for-vinyl
A36: 35 | B36: HiFi.Day at Back2nd.CNX | C36: Thaïlande | D36: Chiang Mai | E36: Basement under Think Park, Nimman, Chiang Mai | F36: Boutique physique | G36: Secondhand vinyl, thrift-style; 100 THB clearance LP box; hi-fi | O36: Rechercher sur Maps | Q36: Actif | R36: =COUNTA(H36:M36) -> 0 | S36: Listed in Time Out Chiang Mai top 11 (c.2025). | T36: https://www.timeout.com/chiang-mai/music/chiang-mais-top-11-places-to-dig-for-vinyl
A37: 36 | B37: Noomtaofire Record | C37: Thaïlande | D37: Chiang Mai | E37: 62/6 Charoen Prathet Rd, Chang Khlan, Mueang Chiang Mai, Chiang Mai 50100 (upstairs of Lonewanderer clothing store) | F37: Boutique physique | G37: New and secondhand vinyl, all genres; small cafe | O37: Rechercher sur Maps | Q37: Actif | R37: =COUNTA(H37:M37) -> 0 | S37: Near the Ping River. Open daily 2pm-7:30pm. | T37: https://www.timeout.com/chiang-mai/music/noomtaofire-record | https://www.timeout.com/chiang-mai/music/chiang-mais-top-11-places-to-dig-for-vinyl
A38: 37 | B38: Thirty Records | C38: Thaïlande | D38: Chiang Mai | E38: 40 Sanambin Kao 4 Alley, Suthep, Mueang Chiang Mai, Chiang Mai 50200 | F38: Boutique physique | G38: Japanese, Thai and Western vinyl; cassettes; hi-fi listening space; budget 3-LP boxes for 100 THB | O38: Rechercher sur Maps | Q38: Actif | R38: =COUNTA(H38:M38) -> 0 | S38: Run by Khun Munee, opened early 2023. Open 11am-6pm, closed Wednesdays. | T38: https://www.timeout.com/chiang-mai/music/thirty-records | https://www.timeout.com/chiang-mai/music/chiang-mais-top-11-places-to-dig-for-vinyl
A39: 38 | B39: Wua Lai Record Shop | C39: Thaïlande | D39: Chiang Mai | E39: 1, 6 Wua Lai Rd, Haiya, Mueang Chiang Mai, Chiang Mai 50100 | F39: Boutique physique | G39: Largest record shop in Chiang Mai; used vinyl incl. Thai rarities (floor boxes, white-label station copies); turntables and speakers | O39: Rechercher sur Maps | Q39: Actif | R39: =COUNTA(H39:M39) -> 0 | S39: Longest-running vinyl seller in town (10+ years). Open 11am-6pm. Listed in Time Out Chiang Mai top 11 (c.2025). | T39: https://www.timeout.com/chiang-mai/music/wua-lai-record-shop | https://www.timeout.com/chiang-mai/music/chiang-mais-top-11-places-to-dig-for-vinyl | https://www.timeout.com/chiang-mai/news/inside-chiang-mais-vinyl-revival-080125
A40: 39 | B40: Sabai Vinyl Pattaya | C40: Thaïlande | D40: Pattaya | E40: 2nd floor, MS2021 (near Eiffel Tower and robot statue), Pattaya | F40: Boutique physique | G40: Vinyl records; buys collections | I40: https://www.instagram.com/sabaivinyl | O40: Rechercher sur Maps | Q40: Non vérifié | R40: =COUNTA(H40:M40) -> 1 | S40: Bills itself as Pattaya's number one record store; open daily 11am-10pm. | T40: https://www.instagram.com/sabaivinyl/
...

Sheet Pokémon
A1: # | B1: Nom | C1: Pays | D1: Ville | E1: Adresse / zone | F1: Type | G1: Taille reseller | H1: Gros items (preuves) | I1: Priorité | J1: Spécialité (langues / produits) | K1: Site web | L1: Instagram | M1: Facebook | N1: TikTok | O1: Téléphone / WhatsApp | P1: Email | Q1: Marketplaces (Shopee, Lazada, Tokopedia…) | R1: Google Maps | S1: Vente en live | T1: Statut | U1: Nb canaux de contact | V1: Notes | W1: Sources
A2: 1 | B2: D Supreme Co., Ltd. (บริษัท ดี ซูพรีม จำกัด) | C2: Thaïlande | F2: Distributeur / grossiste | G2: Gros | H2: Distributes sealed Pokémon TCG product nationwide (booster boxes, premium collections) | I2: =IF(OR(G2="Gros",AND(H2<>"",S2="Oui")),"A",IF(OR(G2="Moyen",H2<>""),"B","C")) -> A | J2: Official sole distributor of Pokémon Trading Card Game in Thailand (per PR) | T2: Actif | U2: =COUNTA(K2:P2) -> 0 | V2: Brand Buffet PR (29 Apr 2026) calls it the sole Pokémon TCG distributor in Thailand; partnered with B2S (Central Retail) on the 'B2S Unseal Go Japan' campaign with The Pokémon Company's support. Contact details not found; HQ city not stated in source. | W2: https://www.brandbuffet.in.th/?p=28007
A3: 2 | B3: B2S | C3: Thaïlande | D3: Bangkok | E3: Nationwide B2S bookstore branches (Central Retail) | F3: Chaîne / grande enseigne | G3: Gros | H3: Premium collection products in Pokémon PLAY LAB | I3: =IF(OR(G3="Gros",AND(H3<>"",S3="Oui")),"A",IF(OR(G3="Moyen",H3<>""),"B","C")) -> A | J3: Pokémon TCG sets & accessories; Pokémon PLAY LAB space; tournaments | R3: Rechercher sur Maps | T3: Actif | U3: =COUNTA(K3:P3) -> 0 | V3: Runs B2S X Pokémon campaigns (B2S-exclusive promo card), the Pokémon PLAY LAB space at B2S CentralWorld, Pokémon PLAY LAB Fun Fest (6-12 Mar), and tournaments at Metro Mall venues (Feb-May 2026). Partner of sole distributor D Supreme. Separate entry for B2S Central Westgate (Nonthaburi). | W3: https://www.marketingoops.com/?p=290143 | https://www.marketingoops.com/?p=360729 | https://www.brandbuffet.in.th/?p=28007 | https://www.lemon8-app.com/@cattymeaw5/7359393930313646609?region=th
A4: 3 | B4: CARDWORLD BKK | C4: Thaïlande | D4: Bangkok | E4: Slow Combo Building, Soi Chula 50, Pathum Wan, Bangkok (near MRT Samyan Exit 2) | F4: Boutique + en ligne | G4: Gros | H4: PSA/BGS/SGC graded slabs; bills itself as Thailand's biggest card shop | I4: =IF(OR(G4="Gros",AND(H4<>"",S4="Oui")),"A",IF(OR(G4="Moyen",H4<>""),"B","C")) -> A | J4: Sports cards, Pokémon & general TCG; graded slabs (PSA/BGS/SGC); live auctions | L4: https://www.instagram.com/cardworld.bkk | R4: Rechercher sur Maps | S4: Oui | T4: Actif | U4: =COUNTA(K4:P4) -> 1 | V4: TCGTalk directory rating 5.0 (297 reviews); runs live auctions | W4: https://tcgtalk.com/guides/tcg-shops-thailand | https://tcgtalk.com/guides/thailand-pokemon-tradeshows-2026 | https://www.instagram.com/cardworld.bkk/ | https://www.lemon8-app.com/@white8z/7619997728135561749?region=th
A5: 4 | B5: Nx Gallery | C5: Thaïlande | D5: Bangkok | E5: Wang Thonglang, Bangkok (outlets near BTS Ari, BTS Phra Khanong, SC Plaza Taling Chan per TCGTalk) | F5: Café / bar avec boutique | G5: Gros | I5: =IF(OR(G5="Gros",AND(H5<>"",S5="Oui")),"A",IF(OR(G5="Moyen",H5<>""),"B","C")) -> A | J5: Pokémon TCG, MTG, One Piece, Union Arena, Gundam; card & board game café | R5: Rechercher sur Maps | T5: Actif | U5: =COUNTA(K5:P5) -> 0 | V5: LINE @nxgallery; multiple outlets (BTS Ari, BTS Phra Khanong, SC Plaza Taling Chan) plus Nx Gallery East in Rayong; TCGTalk 4.9 (256); closed Wednesdays | W5: https://tcgtalk.com/guides/tcg-shops-thailand | https://tcgtalk.com/guides/thailand-pokemon-tradeshows-2026
A6: 5 | B6: Pokémon Center Bangkok | C6: Thaïlande | D6: Bangkok | E6: CentralWorld, C604/2 Level 6, 4, 4/1-4/2, 4/4 Ratchadamri Rd, Pathum Wan, Bangkok 10330 | F6: Chaîne / grande enseigne | G6: Gros | H6: Official sealed TCG product (largest Pokémon Center outside Japan) | I6: =IF(OR(G6="Gros",AND(H6<>"",S6="Oui")),"A",IF(OR(G6="Moyen",H6<>""),"B","C")) -> A | J6: Official Pokémon store: TCG sealed product, plush, gachapon, merchandise | M6: https://www.facebook.com/PokemonThailand | R6: Rechercher sur Maps | T6: Non vérifié | U6: =COUNTA(K6:P6) -> 1 | V6: Official store announced May 2026 (largest Pokémon Center outside Japan); opening slated for late 2026 (Dec 2026 per TCGTalk), so it is not confirmed open as of 8 Oct 2026. The Facebook link is the official Pokémon Thailand page. | W6: https://bulbapedia.bulbagarden.net/wiki/Pok%C3%A9mon_Center_Bangkok | https://www.khaosodenglish.com/life/arts/2026/05/05/thailand-to-get-first-pokemon-center-at-centralworld-in-2026/ | https://sasom.co.th/articles/pok-mon-centre-bangkok-centralworld--thailand-s-first-store-and-the-largest-outside-japan-20260517 | https://www.elitefourum.com/t/pokemon-center-bangkok-to-open-in-2026/62263
A7: 6 | B7: Pika Trading | C7: Thaïlande | D7: Nakhon Ratchasima | E7: 3rd Floor, Terminal 21 Korat, Nakhon Ratchasima | F7: Distributeur / grossiste | G7: Gros | H7: Authorized distributor of sealed Thai-language Pokémon TCG product (per its Lazada listing) | I7: =IF(OR(G7="Gros",AND(H7<>"",S7="Oui")),"A",IF(OR(G7="Moyen",H7<>""),"B","C")) -> A | J7: Thai-language Pokémon TCG (sealed booster packs/boxes); distributor | M7: https://www.facebook.com/pikatrading.th | Q7: Lazada: Pika Trading | T7: Actif | U7: =COUNTA(K7:P7) -> 1 | V7: FB page describes it as a Pokémon card distributor; Lazada listing (SV11S Thai pack) names Pika Trading as authorized distributor of Thai Pokémon cards | W7: https://www.facebook.com/pikatrading.th/ | https://www.lazada.co.th/products/pokemon-booster-pack-sv11s-pokemon-tcg-thai-version-i5799251164.html
A8: 7 | B8: B2S Central Westgate (Pokémon zone) | C8: Thaïlande | D8: Nonthaburi | E8: B2S, Central Westgate, Bang Yai, Nonthaburi | F8: Chaîne / grande enseigne | G8: Gros | H8: Pokémon TCG boxes | I8: =IF(OR(G8="Gros",AND(H8<>"",S8="Oui")),"A",IF(OR(G8="Moyen",H8<>""),"B","C")) -> A | J8: Pokémon zone: TCG packs & boxes, plush, models, play tables | R8: Rechercher sur Maps | T8: Actif | U8: =COUNTA(K8:P8) -> 0 | V8: Branch of B2S chain (see B2S entry); Lemon8 post ~2024 | W8: https://www.lemon8-app.com/@pommeptr/7319060185409044994?region=us
A9: 8 | B9: Big Bear Cards and Hobby | C9: Thaïlande | D9: Bangkok | E9: Thanya Park, Srinagarindra Rd, Suan Luang, Bangkok | F9: Boutique physique | G9: Moyen | I9: =IF(OR(G9="Gros",AND(H9<>"",S9="Oui")),"A",IF(OR(G9="Moyen",H9<>""),"B","C")) -> B | J9: MTG (WPN Premium), Pokémon, Flesh and Blood, Altered, Transformers | R9: Rechercher sur Maps | T9: Actif | U9: =COUNTA(K9:P9) -> 0 | V9: TCGTalk 4.7 (18) | W9: https://tcgtalk.com/guides/tcg-shops-thailand
A10: 9 | B10: Nut Card | C10: Thaïlande | D10: Bangkok | E10: Room A513, 5th Floor, Mega Plaza Saphan Lek (Wang Burapha), Maha Chai Rd, Phra Nakhon, Bangkok | F10: Boutique physique | G10: Moyen | I10: =IF(OR(G10="Gros",AND(H10<>"",S10="Oui")),"A",IF(OR(G10="Moyen",H10<>""),"B","C")) -> B | J10: Pokémon TCG EN/JP/TH; Yu-Gi-Oh!, MTG, One Piece, Cookie Run, Braverse | L10: https://www.instagram.com/nutcard.th | M10: https://www.facebook.com/NutCardTCG | R10: Rechercher sur Maps | T10: Actif | U10: =COUNTA(K10:P10) -> 2 | V10: Hosts Pokémon TCG Town League events; FB page ~27.8k likes; TCGTalk 4.6 (229) | W10: https://tcgtalk.com/guides/tcg-shops-thailand | https://www.facebook.com/NutCardTCG/ | https://www.instagram.com/nutcard.th/
A11: 10 | B11: Pokémon card booth at Mixt Chatuchak (Zone A, Booth Y5) | C11: Thaïlande | D11: Bangkok | E11: 2nd Floor, Zone A, Booth Y5 (near escalator), Mixt Chatuchak, Bangkok (near BTS Mo Chit / MRT Chatuchak Park) | F11: Stand / marché | G11: Moyen | H11: Sells Pokémon boxes (ยกกล่อง) as well as single packs | I11: =IF(OR(G11="Gros",AND(H11<>"",S11="Oui")),"A",IF(OR(G11="Moyen",H11<>""),"B","C")) -> B | J11: Pokémon cards: sealed boxes and packs | R11: Rechercher sur Maps | T11: Actif | U11: =COUNTA(K11:P11) -> 0 | V11: Shop name not shown in result; Lemon8 post by @bearcarecard (~2024) may be the shop's own account | W11: https://www.lemon8-app.com/@bearcarecard/7409195085017498128?region=us
A12: 11 | B12: VG card shop | C12: Thaïlande | D12: Bangkok | E12: 3rd Floor, Room W3-08, The Old Siam Plaza, Pahurat, Bangkok | F12: Boutique + en ligne | G12: Moyen | I12: =IF(OR(G12="Gros",AND(H12<>"",S12="Oui")),"A",IF(OR(G12="Moyen",H12<>""),"B","C")) -> B | J12: Thai-language cards: Pokémon, Vanguard, Buddyfight, Battle Spirits; sleeves, deck boxes, playmats | K12: https://vgcardshop.com | M12: https://www.facebook.com/vgcardshop | O12: 090-279-7603 | R12: Rechercher sur Maps | T12: Actif | U12: =COUNTA(K12:P12) -> 3 | V12: Open Wed-Sun 11:00-17:30; posted singles for sale and a June 2026 event schedule; events posted Aug 2026 | W12: https://www.facebook.com/vgcardshop/
A13: 12 | B13: CaptainCards | C13: Thaïlande | D13: Pathum Thani | E13: 3rd Floor (West zone), Future Park Rangsit, Pathum Thani | F13: Boutique physique | G13: Moyen | I13: =IF(OR(G13="Gros",AND(H13<>"",S13="Oui")),"A",IF(OR(G13="Moyen",H13<>""),"B","C")) -> B | J13: Thai-language Pokémon TCG; TCG accessories | M13: https://www.facebook.com/captaincards | O13: 089-788-8741 | R13: Rechercher sur Maps | T13: Actif | U13: =COUNTA(K13:P13) -> 2 | W13: https://www.facebook.com/captaincards/
A14: 13 | B14: Nx Gallery East | C14: Thaïlande | D14: Rayong | E14: 3rd Floor, Central Plaza Rayong | F14: Café / bar avec boutique | G14: Moyen | I14: =IF(OR(G14="Gros",AND(H14<>"",S14="Oui")),"A",IF(OR(G14="Moyen",H14<>""),"B","C")) -> B | J14: Pokémon, MTG, One Piece, Union Arena, Gundam; TCG accessories | M14: https://www.facebook.com/nxgalleryeast | O14: 063-995-1716 | R14: Rechercher sur Maps | T14: Actif | U14: =COUNTA(K14:P14) -> 2 | V14: Card & board game café; branch of Nx Gallery | W14: https://www.facebook.com/nxgalleryeast/
A15: 14 | B15: CutieLand By POKO | C15: Thaïlande | F15: Vendeur réseaux sociaux | G15: Petit | I15: =IF(OR(G15="Gros",AND(H15<>"",S15="Oui")),"A",IF(OR(G15="Moyen",H15<>""),"B","C")) -> C | J15: Pre-orders of TCG & collectible cards: One Piece, Pokémon, Lorcana; toy store | M15: https://www.facebook.com/cutieland.bypoko | O15: 082-920-3223 | T15: Non vérifié | U15: =COUNTA(K15:P15) -> 2 | W15: https://www.facebook.com/cutieland.bypoko/
A16: 15 | B16: Thai Pkmn | C16: Thaïlande | F16: Vendeur réseaux sociaux | G16: Petit | I16: =IF(OR(G16="Gros",AND(H16<>"",S16="Oui")),"A",IF(OR(G16="Moyen",H16<>""),"B","C")) -> C | J16: Pokémon cards (Thai-based retailer), ships internationally | L16: https://www.instagram.com/thai_pkmn | T16: Non vérifié | U16: =COUNTA(K16:P16) -> 1 | V16: ~900 followers, 225 posts | W16: https://www.instagram.com/thai_pkmn/
A17: 16 | B17: Victory Card Shop | C17: Thaïlande | F17: Boutique physique | G17: Petit | I17: =IF(OR(G17="Gros",AND(H17<>"",S17="Oui")),"A",IF(OR(G17="Moyen",H17<>""),"B","C")) -> C | J17: Buddyfight, Vanguard, Battle Spirits (Pokémon not confirmed; surfaced in Pokémon booster-box search) | M17: https://www.facebook.com/VictoryCardShop | R17: Rechercher sur Maps | T17: Non vérifié | U17: =COUNTA(K17:P17) -> 1 | W17: https://www.facebook.com/VictoryCardShop/
A18: 17 | B18: สหพลการการ์ด (Sahaphon Card) | C18: Thaïlande | D18: Ayutthaya | F18: Boutique physique | G18: Petit | I18: =IF(OR(G18="Gros",AND(H18<>"",S18="Oui")),"A",IF(OR(G18="Moyen",H18<>""),"B","C")) -> C | J18: Pokémon, Battle of Talingchan, hololive, Bushiroad, Bandai products | M18: https://www.facebook.com/SKC3846 | R18: Rechercher sur Maps | T18: Non vérifié | U18: =COUNTA(K18:P18) -> 1 | V18: Claims 100% licensed products | W18: https://www.facebook.com/SKC3846/
A19: 18 | B19: Cardify | C19: Thaïlande | D19: Bangkok | E19: 2nd Floor, Soi Phutthamonthon Sai 1 (Buddhamonthon Lane 1), Phasi Charoen, Bangkok | F19: Boutique physique | G19: Petit | I19: =IF(OR(G19="Gros",AND(H19<>"",S19="Oui")),"A",IF(OR(G19="Moyen",H19<>""),"B","C")) -> C | J19: One Piece, Pokémon, Vanguard, Digimon, Dragon Ball, Ultraman | R19: Rechercher sur Maps | T19: Actif | U19: =COUNTA(K19:P19) -> 0 | V19: TCGTalk 5.0 (117); closed Mondays | W19: https://tcgtalk.com/guides/tcg-shops-thailand
A20: 19 | B20: GL Card Game Shop | C20: Thaïlande | D20: Bangkok | E20: Soi Sathorn 11 Yaek 5, opposite Assumption College Primary Section, Bangkok | F20: Boutique physique | G20: Petit | I20: =IF(OR(G20="Gros",AND(H20<>"",S20="Oui")),"A",IF(OR(G20="Moyen",H20<>""),"B","C")) -> C | J20: Card game shop (Pokémon offer to verify) | M20: https://www.facebook.com/glcardshop | R20: Rechercher sur Maps | T20: Non vérifié | U20: =COUNTA(K20:P20) -> 1 | W20: https://www.facebook.com/glcardshop/
A21: 20 | B21: Nova TCG Thailand | C21: Thaïlande | D21: Bangkok | E21: Ram Inthra 14 area, Bang Khen, Bangkok | F21: Boutique + en ligne | G21: Petit | I21: =IF(OR(G21="Gros",AND(H21<>"",S21="Oui")),"A",IF(OR(G21="Moyen",H21<>""),"B","C")) -> C | J21: Pokémon TCG with focus on Chinese-version (CN) Pokémon cards, accessories, toys, figures | L21: https://www.instagram.com/novatcg.thailand | R21: Rechercher sur Maps | T21: Actif | U21: =COUNTA(K21:P21) -> 1 | V21: TCGTalk 3.8 (26) | W21: https://tcgtalk.com/guides/tcg-shops-thailand | https://www.instagram.com/novatcg.thailand/
A22: 21 | B22: Pro Card | C22: Thaïlande | D22: Bangkok | E22: 5th Floor, MBK Center, Pathum Wan, Bangkok | F22: Boutique physique | G22: Petit | I22: =IF(OR(G22="Gros",AND(H22<>"",S22="Oui")),"A",IF(OR(G22="Moyen",H22<>""),"B","C")) -> C | J22: TCG card shop (Pokémon offer to verify) | M22: https://www.facebook.com/ProcardTCG | R22: Rechercher sur Maps | T22: Non vérifié | U22: =COUNTA(K22:P22) -> 1 | W22: https://www.facebook.com/ProcardTCG/
A23: 22 | B23: Sedai (เซได) | C23: Thaïlande | D23: Bangkok | E23: Sukhumvit 33, near BTS Phrom Phong, Bangkok | F23: Boutique physique | G23: Petit | I23: =IF(OR(G23="Gros",AND(H23<>"",S23="Oui")),"A",IF(OR(G23="Moyen",H23<>""),"B","C")) -> C | J23: Pokémon TCG plus art supplies | M23: https://www.facebook.com/Sedai4.5 | R23: Rechercher sur Maps | T23: Non vérifié | U23: =COUNTA(K23:P23) -> 1 | W23: https://www.facebook.com/Sedai4.5
A24: 23 | B24: Sit and Play | C24: Thaïlande | D24: Bangkok | F24: Boutique physique | G24: Petit | I24: =IF(OR(G24="Gros",AND(H24<>"",S24="Oui")),"A",IF(OR(G24="Moyen",H24<>""),"B","C")) -> C | J24: Pokémon TCG, MTG, Disney Lorcana, One Piece | M24: https://www.facebook.com/sitandplay.game | R24: Rechercher sur Maps | T24: Non vérifié | U24: =COUNTA(K24:P24) -> 1 | W24: https://www.facebook.com/sitandplay.game/
A25: 24 | B25: The Card Shop | C25: Thaïlande | D25: Bangkok | F25: Boutique + en ligne | G25: Petit | I25: =IF(OR(G25="Gros",AND(H25<>"",S25="Oui")),"A",IF(OR(G25="Moyen",H25<>""),"B","C")) -> C | J25: Card games & collectible cards: One Piece Card Game, Union Arena (Pokémon not confirmed) | M25: https://www.facebook.com/TheCardShopTH | O25: 086-056-8454 | R25: Rechercher sur Maps | T25: Non vérifié | U25: =COUNTA(K25:P25) -> 2 | W25: https://www.facebook.com/TheCardShopTH/
A26: 25 | B26: TMshop TCG Store | C26: Thaïlande | D26: Bangkok | E26: 40/11 Soi Sukhumvit 60/1, Bang Chak, Phra Khanong, Bangkok | F26: Boutique physique | G26: Petit | I26: =IF(OR(G26="Gros",AND(H26<>"",S26="Oui")),"A",IF(OR(G26="Moyen",H26<>""),"B","C")) -> C | J26: Collectible & TCG cards (Vanguard etc.) | M26: https://www.facebook.com/tmcardshop | R26: Rechercher sur Maps | T26: Non vérifié | U26: =COUNTA(K26:P26) -> 1 | W26: https://www.facebook.com/tmcardshop/
A27: 26 | B27: Wuwam Card Shop (วู่วามการ์ดชอป) | C27: Thaïlande | D27: Bangkok | E27: Room B236, 2nd Floor, Mega Plaza Saphan Lek, Bangkok | F27: Boutique physique | G27: Petit | I27: =IF(OR(G27="Gros",AND(H27<>"",S27="Oui")),"A",IF(OR(G27="Moyen",H27<>""),"B","C")) -> C | J27: Pokémon EN/JP; buy, sell & trade | M27: https://www.facebook.com/wuwamcardshop | R27: Rechercher sur Maps | T27: Actif | U27: =COUNTA(K27:P27) -> 1 | V27: Mentions Icon Siam / River City (events or branches - unclear) | W27: https://www.facebook.com/wuwamcardshop/
A28: 27 | B28: Tama Card | C28: Thaïlande | D28: Buriram | F28: Boutique physique | G28: Petit | I28: =IF(OR(G28="Gros",AND(H28<>"",S28="Oui")),"A",IF(OR(G28="Moyen",H28<>""),"B","C")) -> C | J28: Card shop (surfaced in Pokémon booster-box searches) | M28: https://www.facebook.com/TAMACardBuriram | R28: Rechercher sur Maps | T28: Non vérifié | U28: =COUNTA(K28:P28) -> 1 | W28: https://www.facebook.com/TAMACardBuriram/
A29: 28 | B29: P'N Card Games Shop | C29: Thaïlande | D29: Chiang Mai | E29: Soi 7, behind Chiang Mai University (near the Faculty of Engineering gate), Chiang Mai | F29: Boutique + en ligne | G29: Petit | I29: =IF(OR(G29="Gros",AND(H29<>"",S29="Oui")),"A",IF(OR(G29="Moyen",H29<>""),"B","C")) -> C | J29: Card game shop incl. Pokémon | L29: https://www.instagram.com/pncardgames | M29: https://www.facebook.com/PNCardGames | Q29: Shopee | R29: Rechercher sur Maps | T29: Actif | U29: =COUNTA(K29:P29) -> 2 | V29: FB page 'P'N Card Game' (~4,380 followers); held a card game tournament in Chiang Mai on 3-4 Oct 2026; sells via Facebook and Shopee (per IG hashtags) | W29: https://www.instagram.com/pncardgames/ | https://www.facebook.com/PNCardGames/
A30: 29 | B30: NK Card Hatyai | C30: Thaïlande | D30: Hat Yai | F30: Boutique physique | G30: Petit | I30: =IF(OR(G30="Gros",AND(H30<>"",S30="Oui")),"A",IF(OR(G30="Moyen",H30<>""),"B","C")) -> C | J30: Pokémon cards and other TCG | M30: https://www.facebook.com/nkcardhatyai | R30: Rechercher sur Maps | T30: Non vérifié | U30: =COUNTA(K30:P30) -> 1 | W30: https://www.facebook.com/nkcardhatyai/
A31: 30 | B31: PokéCore Hua-Hin TCG Shop.TH | C31: Thaïlande | D31: Hua Hin | E31: Near Central Hua Hin, opposite Wat Hua Hin, Prachuap Khiri Khan | F31: Boutique physique | G31: Petit | I31: =IF(OR(G31="Gros",AND(H31<>"",S31="Oui")),"A",IF(OR(G31="Moyen",H31<>""),"B","C")) -> C | J31: Pokémon TCG | R31: Rechercher sur Maps | T31: Actif | U31: =COUNTA(K31:P31) -> 0 | V31: TCGTalk 4.7 (14) | W31: https://tcgtalk.com/guides/tcg-shops-thailand
A32: 31 | B32: DonburiShop TCG KK | C32: Thaïlande | D32: Khon Kaen | F32: Boutique physique | G32: Petit | I32: =IF(OR(G32="Gros",AND(H32<>"",S32="Oui")),"A",IF(OR(G32="Moyen",H32<>""),"B","C")) -> C | J32: TCG shop (surfaced in Pokémon card-shop searches) | M32: https://www.facebook.com/DonburiShopkhonkaen | R32: Rechercher sur Maps | T32: Non vérifié | U32: =COUNTA(K32:P32) -> 1 | W32: https://www.facebook.com/DonburiShopkhonkaen
A33: 32 | B33: Iconic - Trading card game | C33: Thaïlande | D33: Khon Kaen | F33: Distributeur / grossiste | G33: Petit | I33: =IF(OR(G33="Gros",AND(H33<>"",S33="Oui")),"A",IF(OR(G33="Moyen",H33<>""),"B","C")) -> C | J33: Dealer for Vanguard, One Piece, Yu-Gi-Oh, Pokémon | M33: https://www.facebook.com/p/Iconic-Trading-card-game-61576280130672 | T33: Non vérifié | U33: =COUNTA(K33:P33) -> 1 | V33: Page describes itself as distributor/dealer of several card games | W33: https://www.facebook.com/p/Iconic-Trading-card-game-61576280130672/
A34: 33 | B34: Trick Room (Trick Room Card Shop) | C34: Thaïlande | D34: Nakhon Ratchasima | E34: 4th Floor, Central Korat, Nakhon Ratchasima | F34: Boutique physique | G34: Petit | I34: =IF(OR(G34="Gros",AND(H34<>"",S34="Oui")),"A",IF(OR(G34="Moyen",H34<>""),"B","C")) -> C | J34: Pokémon TCG, Battle of Talingchan, Beyblade X; play space / community hub | M34: https://www.facebook.com/TrickRoomCardShop | O34: +66 82 906 6501 | P34: trickroomcardgame@gmail.com | R34: Rechercher sur Maps | T34: Actif | U34: =COUNTA(K34:P34) -> 3 | V34: Has a Linktree; posted about Card Cult & Collectibles Convention 2026 | W34: https://www.facebook.com/TrickRoomCardShop/
A35: 34 | B35: D day card | C35: Thaïlande | D35: Pattaya | E35: 20/198-199 Moo 10, Soi Day Night, Pattaya Tai Rd (next to Tuk Com Pattaya South), Nong Prue, Bang Lamung, Chonburi | F35: Boutique physique | G35: Petit | I35: =IF(OR(G35="Gros",AND(H35<>"",S35="Oui")),"A",IF(OR(G35="Moyen",H35<>""),"B","C")) -> C | J35: Card game products & accessories (Pokémon offer to verify) | M35: https://www.facebook.com/p/D-day-card-100063579728865 | O35: +66 84 567 2356 | R35: Rechercher sur Maps | T35: Non vérifié | U35: =COUNTA(K35:P35) -> 2 | W35: https://www.facebook.com/p/D-day-card-100063579728865/
A36: 35 | B36: TCGIgnition | C36: Thaïlande | D36: Phuket | E36: 369/90 Yaowarat Rd (Soi Yaowarat 5), Talat Yai, Mueang Phuket | F36: Boutique physique | G36: Petit | I36: =IF(OR(G36="Gros",AND(H36<>"",S36="Oui")),"A",IF(OR(G36="Moyen",H36<>""),"B","C")) -> C | J36: Card game hub in Phuket (Pokémon offer not confirmed in snippet) | M36: https://www.facebook.com/p/TCGIgnition-100079263833060 | O36: +66 88 956 1424 | R36: Rechercher sur Maps | T36: Non vérifié | U36: =COUNTA(K36:P36) -> 2 | W36: https://www.facebook.com/p/TCGIgnition-100079263833060/
A37: 36 | B37: BLACK CARD TCG | C37: Thaïlande | D37: Ratchaburi | E37: Moo 3, Pak Raet, Ban Pong, Ratchaburi (event post also references Always One Plaza 5th Fl, Bangkok) | F37: Boutique physique | G37: Petit | I37: =IF(OR(G37="Gros",AND(H37<>"",S37="Oui")),"A",IF(OR(G37="Moyen",H37<>""),"B","C")) -> C | J37: Pokémon, One Piece and other card games | M37: https://www.facebook.com/p/BLACK-CARD-TCG-61583179858522 | O37: 097-146-5424 | R37: Rechercher sur Maps | T37: Actif | U37: =COUNTA(K37:P37) -> 2 | V37: Event dated 20 Sep 2026 | W37: https://www.facebook.com/p/BLACK-CARD-TCG-61583179858522/
A38: 37 | B38: BooM Card Games | C38: Thaïlande | D38: Surat Thani | E38: Sri Chaiya Rd, Talat, Mueang Surat Thani | F38: Boutique physique | G38: Petit | I38: =IF(OR(G38="Gros",AND(H38<>"",S38="Oui")),"A",IF(OR(G38="Moyen",H38<>""),"B","C")) -> C | J38: MTG, Vanguard, Yu-Gi-Oh, Battle of Talingchan, Lorcana; sleeves, deck boxes (Pokémon not listed in snippet) | M38: https://www.facebook.com/BooMCardGames | R38: Rechercher sur Maps | T38: Non vérifié | U38: =COUNTA(K38:P38) -> 1 | W38: https://www.facebook.com/BooMCardGames/
A39: 38 | B39: A&E บุ๊ค แอนด์ การ์ด (A&E Book and Card) | C39: Thaïlande | F39: Boutique physique | G39: Inconnu | I39: =IF(OR(G39="Gros",AND(H39<>"",S39="Oui")),"A",IF(OR(G39="Moyen",H39<>""),"B","C")) -> C | J39: Books & cards (surfaced in Pokémon booster-box searches) | M39: https://www.facebook.com/p/AE-%E0%B8%9A%E0%B8%B8%E0%B9%8A%E0%B8%84-%E0%B9%81%E0%B8%AD%E0%B8%99%E0%B8%94%E0%B9%8C-%E0%B8%81%E0%B8%B2%E0%B8%A3%E0%B9%8C%E0%B8%94-100083350831800 | R39: Rechercher sur Maps | T39: Non vérifié | U39: =COUNTA(K39:P39) -> 1 | W39: https://www.facebook.com/p/AE-%E0%B8%9A%E0%B8%B8%E0%B9%8A%E0%B8%84-%E0%B9%81%E0%B8%AD%E0%B8%99%E0%B8%94%E0%B9%8C-%E0%B8%81%E0%B8%B2%E0%B8%A3%E0%B9%8C%E0%B8%94-100083350831800/
A40: 39 | B40: ANNA SHOP | C40: Thaïlande | F40: Vendeur réseaux sociaux | G40: Inconnu | I40: =IF(OR(G40="Gros",AND(H40<>"",S40="Oui")),"A",IF(OR(G40="Moyen",H40<>""),"B","C")) -> C | J40: Surfaced in Thai search for Japanese Pokémon booster boxes; details not visible | M40: https://www.facebook.com/p/ANNA-SHOP-100063683825022 | T40: Non vérifié | U40: =COUNTA(K40:P40) -> 1 | W40: https://www.facebook.com/p/ANNA-SHOP-100063683825022/
...
